Workbook

Sheet Form Responses 1
A1: Timestamp | B1: Nama Lengkap | C1: Email | D1: Nomor WhatsApp | E1: Domisili | F1: Apakah Anda Mahasiswa / Fresh Graduate | G1: Pekerjaan & Instansi Saat Ini | H1: Tools yang Ingin Dipelajari | I1: Target Join Komunitas | J1: Tau Seara Data Dari Mana? | K1: Column 1 | L1: Provinsi | M1: Cari Kerja | N1: Upskill | O1: Networking | P1: Switch Career
A2: 46049.123 | B2: Aarif Rahmaan Jalaluddin Faqiih | C2: aarifrjf@gmail.com | D2: 082242458593 | E2: Jawa Tengah | F2: Ya | G2: Mahasiswa | H2: Python, Tableau | I2: Cari Kerja, Upskill, Networking | J2: LinkedIn | K2: =IF(LEFT(D2,2)="62","0"&MID(D2,3,LEN(D2)),D2) -> 082242458593 | L2: =IFERROR( VLOOKUP( TRIM( IF(ISNUMBER(FIND(",",E2)), LEFT(E2,FIND(",",E2)-1), E2 ) ), master!A:B, 2, FALSE ), "Belum ada mapping" ) -> Jawa Tengah | M2: =IFERROR(__xludf.DUMMYFUNCTION("IF(REGEXMATCH(I2,""Cari Kerja""),1,0) "),1.0) -> 1 | N2: =IFERROR(__xludf.DUMMYFUNCTION("IF(REGEXMATCH(I2,""Upskill""),1,0) "),1.0) -> 1 | O2: =IFERROR(__xludf.DUMMYFUNCTION("IF(REGEXMATCH(I2,""Networking""),1,0) "),1.0) -> 1 | P2: =IFERROR(__xludf.DUMMYFUNCTION("IF(REGEXMATCH(I2,""Switch Career""),1,0) "),0.0) -> 0
A3: 46041.4 | B3: Abdullah Rajab Sani | C3: abdullahrsani@gmail.com | D3: 089636422658 | E3: Padang | F3: Ya | G3: belum ada | H3: Excel, SQL, Python, Power BI | I3: Cari Kerja, Upskill, Networking, Switch Career | J3: LinkedIn | K3: =IF(LEFT(D3,2)="62","0"&MID(D3,3,LEN(D3)),D3) -> 089636422658 | L3: =IFERROR( VLOOKUP( TRIM( IF(ISNUMBER(FIND(",",E3)), LEFT(E3,FIND(",",E3)-1), E3 ) ), master!A:B, 2, FALSE ), "Belum ada mapping" ) -> Sumatera Barat | M3: =IFERROR(__xludf.DUMMYFUNCTION("IF(REGEXMATCH(I3,""Cari Kerja""),1,0) "),1.0) -> 1 | N3: =IFERROR(__xludf.DUMMYFUNCTION("IF(REGEXMATCH(I3,""Upskill""),1,0) "),1.0) -> 1 | O3: =IFERROR(__xludf.DUMMYFUNCTION("IF(REGEXMATCH(I3,""Networking""),1,0) "),1.0) -> 1 | P3: =IFERROR(__xludf.DUMMYFUNCTION("IF(REGEXMATCH(I3,""Switch Career""),1,0) "),1.0) -> 1
A4: 46159.859 | B4: Abdur Rochman | C4: abdurrochman195@gmail.com | D4: 085785757834 | E4: Surabaya | F4: Ya | G4: Freelance Web Development | H4: Excel, SQL, Python, Power BI, Databases | I4: Cari Kerja, Upskill, Networking | J4: Teman | K4: =IF(LEFT(D4,2)="62","0"&MID(D4,3,LEN(D4)),D4) -> 085785757834 | L4: =IFERROR( VLOOKUP( TRIM( IF(ISNUMBER(FIND(",",E4)), LEFT(E4,FIND(",",E4)-1), E4 ) ), master!A:B, 2, FALSE ), "Belum ada mapping" ) -> Jawa Timur | M4: =IFERROR(__xludf.DUMMYFUNCTION("IF(REGEXMATCH(I4,""Cari Kerja""),1,0) "),1.0) -> 1 | N4: =IFERROR(__xludf.DUMMYFUNCTION("IF(REGEXMATCH(I4,""Upskill""),1,0) "),1.0) -> 1 | O4: =IFERROR(__xludf.DUMMYFUNCTION("IF(REGEXMATCH(I4,""Networking""),1,0) "),1.0) -> 1 | P4: =IFERROR(__xludf.DUMMYFUNCTION("IF(REGEXMATCH(I4,""Switch Career""),1,0) "),0.0) -> 0
A5: 46043.57 | B5: Abdurrahman Qeis Ahmad | C5: qeisahmad98@gmail.com | D5: 0895421552311 | E5: Bandung | F5: Ya | G5: Konsultan Perencanaan Kota | H5: Python, Power BI | I5: Upskill | J5: LinkedIn | K5: =IF(LEFT(D5,2)="62","0"&MID(D5,3,LEN(D5)),D5) -> 0895421552311 | L5: =IFERROR( VLOOKUP( TRIM( IF(ISNUMBER(FIND(",",E5)), LEFT(E5,FIND(",",E5)-1), E5 ) ), master!A:B, 2, FALSE ), "Belum ada mapping" ) -> Jawa Barat | M5: =IFERROR(__xludf.DUMMYFUNCTION("IF(REGEXMATCH(I5,""Cari Kerja""),1,0) "),0.0) -> 0 | N5: =IFERROR(__xludf.DUMMYFUNCTION("IF(REGEXMATCH(I5,""Upskill""),1,0) "),1.0) -> 1 | O5: =IFERROR(__xludf.DUMMYFUNCTION("IF(REGEXMATCH(I5,""Networking""),1,0) "),0.0) -> 0 | P5: =IFERROR(__xludf.DUMMYFUNCTION("IF(REGEXMATCH(I5,""Switch Career""),1,0) "),0.0) -> 0
A6: 46043.298 | B6: Abid Maulana Akbar | C6: abidma012@gmail.com | D6: 085803655302 | E6: Yogyakarta | F6: Tidak | G6: Senior Barista _- Esha kopi | H6: Excel, SQL, Python, Power BI, Looker Studio, Databases, Tableau | I6: Upskill, Networking, Switch Career | J6: Teman | K6: =IF(LEFT(D6,2)="62","0"&MID(D6,3,LEN(D6)),D6) -> 085803655302 | L6: =IFERROR( VLOOKUP( TRIM( IF(ISNUMBER(FIND(",",E6)), LEFT(E6,FIND(",",E6)-1), E6 ) ), master!A:B, 2, FALSE ), "Belum ada mapping" ) -> DI Yogyakarta | M6: =IFERROR(__xludf.DUMMYFUNCTION("IF(REGEXMATCH(I6,""Cari Kerja""),1,0) "),0.0) -> 0 | N6: =IFERROR(__xludf.DUMMYFUNCTION("IF(REGEXMATCH(I6,""Upskill""),1,0) "),1.0) -> 1 | O6: =IFERROR(__xludf.DUMMYFUNCTION("IF(REGEXMATCH(I6,""Networking""),1,0) "),1.0) -> 1 | P6: =IFERROR(__xludf.DUMMYFUNCTION("IF(REGEXMATCH(I6,""Switch Career""),1,0) "),1.0) -> 1
A7: 46040.433 | B7: Abimanyu Priyatno | C7: abimanyupri@gmail.com | D7: 085692331114 | E7: Tangerang | F7: Ya | G7: Data & Informasi System Staff, Kementerian Desa PDT | H7: Excel, SQL, Power BI, Tableau | I7: Upskill, Networking | J7: Teman | K7: =IF(LEFT(D7,2)="62","0"&MID(D7,3,LEN(D7)),D7) -> 085692331114 | L7: =IFERROR( VLOOKUP( TRIM( IF(ISNUMBER(FIND(",",E7)), LEFT(E7,FIND(",",E7)-1), E7 ) ), master!A:B, 2, FALSE ), "Belum ada mapping" ) -> Banten | M7: =IFERROR(__xludf.DUMMYFUNCTION("IF(REGEXMATCH(I7,""Cari Kerja""),1,0) "),0.0) -> 0 | N7: =IFERROR(__xludf.DUMMYFUNCTION("IF(REGEXMATCH(I7,""Upskill""),1,0) "),1.0) -> 1 | O7: =IFERROR(__xludf.DUMMYFUNCTION("IF(REGEXMATCH(I7,""Networking""),1,0) "),1.0) -> 1 | P7: =IFERROR(__xludf.DUMMYFUNCTION("IF(REGEXMATCH(I7,""Switch Career""),1,0) "),0.0) -> 0
A8: 46045.478 | B8: Achmad Chilmi Syifa | C8: hylmisyifa@gmail.com | D8: 083843588880 | E8: Kudus | F8: Tidak | G8: Admin Personalia | H8: Excel, SQL, Python, Power BI, Looker Studio, Databases, Tableau | I8: Cari Kerja, Upskill, Networking, Switch Career | J8: LinkedIn | K8: =IF(LEFT(D8,2)="62","0"&MID(D8,3,LEN(D8)),D8) -> 083843588880 | L8: =IFERROR( VLOOKUP( TRIM( IF(ISNUMBER(FIND(",",E8)), LEFT(E8,FIND(",",E8)-1), E8 ) ), master!A:B, 2, FALSE ), "Belum ada mapping" ) -> Jawa Tengah | M8: =IFERROR(__xludf.DUMMYFUNCTION("IF(REGEXMATCH(I8,""Cari Kerja""),1,0) "),1.0) -> 1 | N8: =IFERROR(__xludf.DUMMYFUNCTION("IF(REGEXMATCH(I8,""Upskill""),1,0) "),1.0) -> 1 | O8: =IFERROR(__xludf.DUMMYFUNCTION("IF(REGEXMATCH(I8,""Networking""),1,0) "),1.0) -> 1 | P8: =IFERROR(__xludf.DUMMYFUNCTION("IF(REGEXMATCH(I8,""Switch Career""),1,0) "),1.0) -> 1
A9: 46041.399 | B9: Achmad jamaah firdaus | C9: Achmadjamaahfirdaus0099@gmail.com | D9: 083865555032 | E9: Boyolali | F9: Ya | G9: - | H9: Excel, SQL, Python, Power BI, Looker Studio, Databases, Airflow | I9: Cari Kerja, Upskill, Networking | J9: LinkedIn | K9: =IF(LEFT(D9,2)="62","0"&MID(D9,3,LEN(D9)),D9) -> 083865555032 | L9: =IFERROR( VLOOKUP( TRIM( IF(ISNUMBER(FIND(",",E9)), LEFT(E9,FIND(",",E9)-1), E9 ) ), master!A:B, 2, FALSE ), "Belum ada mapping" ) -> Jawa Tengah | M9: =IFERROR(__xludf.DUMMYFUNCTION("IF(REGEXMATCH(I9,""Cari Kerja""),1,0) "),1.0) -> 1 | N9: =IFERROR(__xludf.DUMMYFUNCTION("IF(REGEXMATCH(I9,""Upskill""),1,0) "),1.0) -> 1 | O9: =IFERROR(__xludf.DUMMYFUNCTION("IF(REGEXMATCH(I9,""Networking""),1,0) "),1.0) -> 1 | P9: =IFERROR(__xludf.DUMMYFUNCTION("IF(REGEXMATCH(I9,""Switch Career""),1,0) "),0.0) -> 0
A10: 46045.612 | B10: Achmad Kurniansyah | C10: achmadkurniansyahthalib@gmail.com | D10: 087814074676 | E10: Tangerang | F10: Tidak | G10: Senior Business Intelegence Dekoruma | H10: Excel, SQL, Python, Power BI, Looker Studio, Databases, Tableau | I10: Upskill, Networking | J10: Instagram | K10: =IF(LEFT(D10,2)="62","0"&MID(D10,3,LEN(D10)),D10) -> 087814074676 | L10: =IFERROR( VLOOKUP( TRIM( IF(ISNUMBER(FIND(",",E10)), LEFT(E10,FIND(",",E10)-1), E10 ) ), master!A:B, 2, FALSE ), "Belum ada mapping" ) -> Banten | M10: =IFERROR(__xludf.DUMMYFUNCTION("IF(REGEXMATCH(I10,""Cari Kerja""),1,0) "),0.0) -> 0 | N10: =IFERROR(__xludf.DUMMYFUNCTION("IF(REGEXMATCH(I10,""Upskill""),1,0) "),1.0) -> 1 | O10: =IFERROR(__xludf.DUMMYFUNCTION("IF(REGEXMATCH(I10,""Networking""),1,0) "),1.0) -> 1 | P10: =IFERROR(__xludf.DUMMYFUNCTION("IF(REGEXMATCH(I10,""Switch Career""),1,0) "),0.0) -> 0
A11: 46045.711 | B11: Addo Adantya Abiesa | C11: abiesa.addo@gmail.com | D11: 087776964621 | E11: Sidoarjo, Jawa Timur | F11: Tidak | G11: Audit - PT Jawa Berkat Indonesia | H11: Excel, SQL, Python, Power BI, Looker Studio, Tableau | I11: Cari Kerja, Upskill, Networking, Switch Career | J11: Teman | K11: =IF(LEFT(D11,2)="62","0"&MID(D11,3,LEN(D11)),D11) -> 087776964621 | L11: =IFERROR( VLOOKUP( TRIM( IF(ISNUMBER(FIND(",",E11)), LEFT(E11,FIND(",",E11)-1), E11 ) ), master!A:B, 2, FALSE ), "Belum ada mapping" ) -> Jawa Timur | M11: =IFERROR(__xludf.DUMMYFUNCTION("IF(REGEXMATCH(I11,""Cari Kerja""),1,0) "),1.0) -> 1 | N11: =IFERROR(__xludf.DUMMYFUNCTION("IF(REGEXMATCH(I11,""Upskill""),1,0) "),1.0) -> 1 | O11: =IFERROR(__xludf.DUMMYFUNCTION("IF(REGEXMATCH(I11,""Networking""),1,0) "),1.0) -> 1 | P11: =IFERROR(__xludf.DUMMYFUNCTION("IF(REGEXMATCH(I11,""Switch Career""),1,0) "),1.0) -> 1
A12: 46134.695 | B12: Ade Krisna | C12: adekrisnasubagyo18@gmail.com | D12: 082228461957 | E12: Banyumas | F12: Ya | G12: - | H12: Excel, SQL, Python, Power BI, Looker Studio, Databases | I12: Cari Kerja | J12: Instagram | K12: =IF(LEFT(D12,2)="62","0"&MID(D12,3,LEN(D12)),D12) -> 082228461957 | L12: =IFERROR( VLOOKUP( TRIM( IF(ISNUMBER(FIND(",",E12)), LEFT(E12,FIND(",",E12)-1), E12 ) ), master!A:B, 2, FALSE ), "Belum ada mapping" ) -> Jawa Tengah | M12: =IFERROR(__xludf.DUMMYFUNCTION("IF(REGEXMATCH(I12,""Cari Kerja""),1,0) "),1.0) -> 1 | N12: =IFERROR(__xludf.DUMMYFUNCTION("IF(REGEXMATCH(I12,""Upskill""),1,0) "),0.0) -> 0 | O12: =IFERROR(__xludf.DUMMYFUNCTION("IF(REGEXMATCH(I12,""Networking""),1,0) "),0.0) -> 0 | P12: =IFERROR(__xludf.DUMMYFUNCTION("IF(REGEXMATCH(I12,""Switch Career""),1,0) "),0.0) -> 0
A13: 46046.568 | B13: Ade Krisna Subagyo | C13: adekrisnasubagyo18@gmail.com | D13: 082228461957 | E13: Jawa Tengah | F13: Ya | G13: - | H13: Excel, SQL, Python, Power BI, Looker Studio, Databases, Tableau | I13: Cari Kerja, Upskill, Networking | J13: LinkedIn | K13: =IF(LEFT(D13,2)="62","0"&MID(D13,3,LEN(D13)),D13) -> 082228461957 | L13: =IFERROR( VLOOKUP( TRIM( IF(ISNUMBER(FIND(",",E13)), LEFT(E13,FIND(",",E13)-1), E13 ) ), master!A:B, 2, FALSE ), "Belum ada mapping" ) -> Jawa Tengah | M13: =IFERROR(__xludf.DUMMYFUNCTION("IF(REGEXMATCH(I13,""Cari Kerja""),1,0) "),1.0) -> 1 | N13: =IFERROR(__xludf.DUMMYFUNCTION("IF(REGEXMATCH(I13,""Upskill""),1,0) "),1.0) -> 1 | O13: =IFERROR(__xludf.DUMMYFUNCTION("IF(REGEXMATCH(I13,""Networking""),1,0) "),1.0) -> 1 | P13: =IFERROR(__xludf.DUMMYFUNCTION("IF(REGEXMATCH(I13,""Switch Career""),1,0) "),0.0) -> 0
A14: 46046.415 | B14: Ade Mutia | C14: ademutia.suwardi@gmail.com | D14: 085862612541 | E14: Bekasi | F14: Ya | G14: - | H14: Excel, SQL, Python, Power BI, Tableau | I14: Upskill | J14: Teman | K14: =IF(LEFT(D14,2)="62","0"&MID(D14,3,LEN(D14)),D14) -> 085862612541 | L14: =IFERROR( VLOOKUP( TRIM( IF(ISNUMBER(FIND(",",E14)), LEFT(E14,FIND(",",E14)-1), E14 ) ), master!A:B, 2, FALSE ), "Belum ada mapping" ) -> Jawa Barat | M14: =IFERROR(__xludf.DUMMYFUNCTION("IF(REGEXMATCH(I14,""Cari Kerja""),1,0) "),0.0) -> 0 | N14: =IFERROR(__xludf.DUMMYFUNCTION("IF(REGEXMATCH(I14,""Upskill""),1,0) "),1.0) -> 1 | O14: =IFERROR(__xludf.DUMMYFUNCTION("IF(REGEXMATCH(I14,""Networking""),1,0) "),0.0) -> 0 | P14: =IFERROR(__xludf.DUMMYFUNCTION("IF(REGEXMATCH(I14,""Switch Career""),1,0) "),0.0) -> 0
A15: 46045.807 | B15: Ade Tri Oktavian | C15: adetrioktavian12@gmail.com | D15: 081380305890 | E15: Jakarta Timur | F15: Tidak | G15: Warehouse - Supply Chain | H15: Excel, SQL, Python, Power BI | I15: Upskill, Networking | J15: LinkedIn | K15: =IF(LEFT(D15,2)="62","0"&MID(D15,3,LEN(D15)),D15) -> 081380305890 | L15: =IFERROR( VLOOKUP( TRIM( IF(ISNUMBER(FIND(",",E15)), LEFT(E15,FIND(",",E15)-1), E15 ) ), master!A:B, 2, FALSE ), "Belum ada mapping" ) -> Jakarta | M15: =IFERROR(__xludf.DUMMYFUNCTION("IF(REGEXMATCH(I15,""Cari Kerja""),1,0) "),0.0) -> 0 | N15: =IFERROR(__xludf.DUMMYFUNCTION("IF(REGEXMATCH(I15,""Upskill""),1,0) "),1.0) -> 1 | O15: =IFERROR(__xludf.DUMMYFUNCTION("IF(REGEXMATCH(I15,""Networking""),1,0) "),1.0) -> 1 | P15: =IFERROR(__xludf.DUMMYFUNCTION("IF(REGEXMATCH(I15,""Switch Career""),1,0) "),0.0) -> 0
A16: 46047.994 | B16: Adek Putri | C16: adek19putri@gmail.com | D16: 08116681815 | E16: Padang | F16: Tidak | G16: ASN | H16: Excel, SQL, Python, Power BI, Looker Studio, Databases, Tableau, Anything | I16: Cari Kerja, Upskill, Networking, Switch Career | J16: LinkedIn | K16: =IF(LEFT(D16,2)="62","0"&MID(D16,3,LEN(D16)),D16) -> 08116681815 | L16: =IFERROR( VLOOKUP( TRIM( IF(ISNUMBER(FIND(",",E16)), LEFT(E16,FIND(",",E16)-1), E16 ) ), master!A:B, 2, FALSE ), "Belum ada mapping" ) -> Sumatera Barat | M16: =IFERROR(__xludf.DUMMYFUNCTION("IF(REGEXMATCH(I16,""Cari Kerja""),1,0) "),1.0) -> 1 | N16: =IFERROR(__xludf.DUMMYFUNCTION("IF(REGEXMATCH(I16,""Upskill""),1,0) "),1.0) -> 1 | O16: =IFERROR(__xludf.DUMMYFUNCTION("IF(REGEXMATCH(I16,""Networking""),1,0) "),1.0) -> 1 | P16: =IFERROR(__xludf.DUMMYFUNCTION("IF(REGEXMATCH(I16,""Switch Career""),1,0) "),1.0) -> 1
A17: 46042.408 | B17: Adhyatnika Nugraha | C17: adhyatnika.nugraha@gmail.com | D17: 081803539087 | E17: Cianjur | F17: Tidak | G17: Staff HR di salah satu Bank Swasta | H17: Excel, SQL, Python, Power BI, Databases | I17: Cari Kerja, Networking | J17: Teman | K17: =IF(LEFT(D17,2)="62","0"&MID(D17,3,LEN(D17)),D17) -> 081803539087 | L17: =IFERROR( VLOOKUP( TRIM( IF(ISNUMBER(FIND(",",E17)), LEFT(E17,FIND(",",E17)-1), E17 ) ), master!A:B, 2, FALSE ), "Belum ada mapping" ) -> Jawa Barat | M17: =IFERROR(__xludf.DUMMYFUNCTION("IF(REGEXMATCH(I17,""Cari Kerja""),1,0) "),1.0) -> 1 | N17: =IFERROR(__xludf.DUMMYFUNCTION("IF(REGEXMATCH(I17,""Upskill""),1,0) "),0.0) -> 0 | O17: =IFERROR(__xludf.DUMMYFUNCTION("IF(REGEXMATCH(I17,""Networking""),1,0) "),1.0) -> 1 | P17: =IFERROR(__xludf.DUMMYFUNCTION("IF(REGEXMATCH(I17,""Switch Career""),1,0) "),0.0) -> 0
A18: 46040.506 | B18: Adi Syah Putra Simbolon | C18: adisyahsimbolon@gamil.con | D18: 085372235592 | E18: Medan | F18: Tidak | G18: Idle | H18: Excel, SQL, Python, Power BI, Looker Studio, Databases, Tableau | I18: Cari Kerja, Upskill, Networking, Switch Career | J18: LinkedIn | K18: =IF(LEFT(D18,2)="62","0"&MID(D18,3,LEN(D18)),D18) -> 085372235592 | L18: =IFERROR( VLOOKUP( TRIM( IF(ISNUMBER(FIND(",",E18)), LEFT(E18,FIND(",",E18)-1), E18 ) ), master!A:B, 2, FALSE ), "Belum ada mapping" ) -> Sumatera Utara | M18: =IFERROR(__xludf.DUMMYFUNCTION("IF(REGEXMATCH(I18,""Cari Kerja""),1,0) "),1.0) -> 1 | N18: =IFERROR(__xludf.DUMMYFUNCTION("IF(REGEXMATCH(I18,""Upskill""),1,0) "),1.0) -> 1 | O18: =IFERROR(__xludf.DUMMYFUNCTION("IF(REGEXMATCH(I18,""Networking""),1,0) "),1.0) -> 1 | P18: =IFERROR(__xludf.DUMMYFUNCTION("IF(REGEXMATCH(I18,""Switch Career""),1,0) "),1.0) -> 1
A19: 46042.531 | B19: Adinda Dwi Nur Rahmawati | C19: dadinda868@gmail.com | D19: 088989430679 | E19: Gresik | F19: Ya | G19: Mahasiswa | H19: Excel, SQL, Python, Power BI, Tableau | I19: Cari Kerja, Upskill, Networking | J19: LinkedIn | K19: =IF(LEFT(D19,2)="62","0"&MID(D19,3,LEN(D19)),D19) -> 088989430679 | L19: =IFERROR( VLOOKUP( TRIM( IF(ISNUMBER(FIND(",",E19)), LEFT(E19,FIND(",",E19)-1), E19 ) ), master!A:B, 2, FALSE ), "Belum ada mapping" ) -> Jawa Timur | M19: =IFERROR(__xludf.DUMMYFUNCTION("IF(REGEXMATCH(I19,""Cari Kerja""),1,0) "),1.0) -> 1 | N19: =IFERROR(__xludf.DUMMYFUNCTION("IF(REGEXMATCH(I19,""Upskill""),1,0) "),1.0) -> 1 | O19: =IFERROR(__xludf.DUMMYFUNCTION("IF(REGEXMATCH(I19,""Networking""),1,0) "),1.0) -> 1 | P19: =IFERROR(__xludf.DUMMYFUNCTION("IF(REGEXMATCH(I19,""Switch Career""),1,0) "),0.0) -> 0
A20: 46043.383 | B20: Adinda Dwi Putri | C20: dindaadwptri@gmail.com | D20: 085256392566 | E20: Makassar | F20: Ya | G20: Quality System Intern | H20: Excel, SQL, Python, Power BI, Looker Studio, Databases, Tableau | I20: Cari Kerja, Upskill, Networking | J20: LinkedIn | K20: =IF(LEFT(D20,2)="62","0"&MID(D20,3,LEN(D20)),D20) -> 085256392566 | L20: =IFERROR( VLOOKUP( TRIM( IF(ISNUMBER(FIND(",",E20)), LEFT(E20,FIND(",",E20)-1), E20 ) ), master!A:B, 2, FALSE ), "Belum ada mapping" ) -> Sulawesi Selatan | M20: =IFERROR(__xludf.DUMMYFUNCTION("IF(REGEXMATCH(I20,""Cari Kerja""),1,0) "),1.0) -> 1 | N20: =IFERROR(__xludf.DUMMYFUNCTION("IF(REGEXMATCH(I20,""Upskill""),1,0) "),1.0) -> 1 | O20: =IFERROR(__xludf.DUMMYFUNCTION("IF(REGEXMATCH(I20,""Networking""),1,0) "),1.0) -> 1 | P20: =IFERROR(__xludf.DUMMYFUNCTION("IF(REGEXMATCH(I20,""Switch Career""),1,0) "),0.0) -> 0
A21: 46042.292 | B21: Adinda Putri Satya | C21: putrisd188@gmail.com | D21: 081221196013 | E21: Jawa Barat, | F21: Ya | G21: Freshgraduated | H21: Excel, SQL, Power BI, Looker Studio | I21: Cari Kerja, Upskill | J21: LinkedIn | K21: =IF(LEFT(D21,2)="62","0"&MID(D21,3,LEN(D21)),D21) -> 081221196013 | L21: =IFERROR( VLOOKUP( TRIM( IF(ISNUMBER(FIND(",",E21)), LEFT(E21,FIND(",",E21)-1), E21 ) ), master!A:B, 2, FALSE ), "Belum ada mapping" ) -> Jawa Barat | M21: =IFERROR(__xludf.DUMMYFUNCTION("IF(REGEXMATCH(I21,""Cari Kerja""),1,0) "),1.0) -> 1 | N21: =IFERROR(__xludf.DUMMYFUNCTION("IF(REGEXMATCH(I21,""Upskill""),1,0) "),1.0) -> 1 | O21: =IFERROR(__xludf.DUMMYFUNCTION("IF(REGEXMATCH(I21,""Networking""),1,0) "),0.0) -> 0 | P21: =IFERROR(__xludf.DUMMYFUNCTION("IF(REGEXMATCH(I21,""Switch Career""),1,0) "),0.0) -> 0
A22: 46046.61 | B22: Adinda Rahma Illawati | C22: rdinda659@gmail.com | D22: 089524739800 | E22: Bandung | F22: Ya | G22: Magang - Pemerintahan (BBPMP Jabar) | H22: Power BI, Looker Studio, Tableau | I22: Cari Kerja, Upskill | J22: LinkedIn | K22: =IF(LEFT(D22,2)="62","0"&MID(D22,3,LEN(D22)),D22) -> 089524739800 | L22: =IFERROR( VLOOKUP( TRIM( IF(ISNUMBER(FIND(",",E22)), LEFT(E22,FIND(",",E22)-1), E22 ) ), master!A:B, 2, FALSE ), "Belum ada mapping" ) -> Jawa Barat | M22: =IFERROR(__xludf.DUMMYFUNCTION("IF(REGEXMATCH(I22,""Cari Kerja""),1,0) "),1.0) -> 1 | N22: =IFERROR(__xludf.DUMMYFUNCTION("IF(REGEXMATCH(I22,""Upskill""),1,0) "),1.0) -> 1 | O22: =IFERROR(__xludf.DUMMYFUNCTION("IF(REGEXMATCH(I22,""Networking""),1,0) "),0.0) -> 0 | P22: =IFERROR(__xludf.DUMMYFUNCTION("IF(REGEXMATCH(I22,""Switch Career""),1,0) "),0.0) -> 0
A23: 46040.487 | B23: Aditya Rizky Widiarta | C23: adityawidiarta0@gmail.com | D23: 08119255511 | E23: Bekasi | F23: Tidak | G23: PT SOKKA TAMA FIBER | H23: Excel, SQL, Python, Power BI, Looker Studio, Databases, Tableau | I23: Upskill, Networking, Switch Career | J23: Instagram | K23: =IF(LEFT(D23,2)="62","0"&MID(D23,3,LEN(D23)),D23) -> 08119255511 | L23: =IFERROR( VLOOKUP( TRIM( IF(ISNUMBER(FIND(",",E23)), LEFT(E23,FIND(",",E23)-1), E23 ) ), master!A:B, 2, FALSE ), "Belum ada mapping" ) -> Jawa Barat | M23: =IFERROR(__xludf.DUMMYFUNCTION("IF(REGEXMATCH(I23,""Cari Kerja""),1,0) "),0.0) -> 0 | N23: =IFERROR(__xludf.DUMMYFUNCTION("IF(REGEXMATCH(I23,""Upskill""),1,0) "),1.0) -> 1 | O23: =IFERROR(__xludf.DUMMYFUNCTION("IF(REGEXMATCH(I23,""Networking""),1,0) "),1.0) -> 1 | P23: =IFERROR(__xludf.DUMMYFUNCTION("IF(REGEXMATCH(I23,""Switch Career""),1,0) "),1.0) -> 1
A24: 46042.517 | B24: Adrian Taufan | C24: adriantaufan3129@gmail.com | D24: 081356910981 | E24: Tangerang | F24: Ya | G24: Student | H24: Excel, SQL, Python, Power BI, Looker Studio, Databases, Tableau | I24: Upskill, Networking | J24: LinkedIn | K24: =IF(LEFT(D24,2)="62","0"&MID(D24,3,LEN(D24)),D24) -> 081356910981 | L24: =IFERROR( VLOOKUP( TRIM( IF(ISNUMBER(FIND(",",E24)), LEFT(E24,FIND(",",E24)-1), E24 ) ), master!A:B, 2, FALSE ), "Belum ada mapping" ) -> Banten | M24: =IFERROR(__xludf.DUMMYFUNCTION("IF(REGEXMATCH(I24,""Cari Kerja""),1,0) "),0.0) -> 0 | N24: =IFERROR(__xludf.DUMMYFUNCTION("IF(REGEXMATCH(I24,""Upskill""),1,0) "),1.0) -> 1 | O24: =IFERROR(__xludf.DUMMYFUNCTION("IF(REGEXMATCH(I24,""Networking""),1,0) "),1.0) -> 1 | P24: =IFERROR(__xludf.DUMMYFUNCTION("IF(REGEXMATCH(I24,""Switch Career""),1,0) "),0.0) -> 0
A25: 46040.496 | B25: Afdhal Wirahadi | C25: afdhal.wirahadi@gmail.com | D25: 081316016661 | E25: Dumai | F25: Tidak | G25: Freelance | H25: Excel, SQL, Python, Power BI, Tableau | I25: Upskill | J25: LinkedIn | K25: =IF(LEFT(D25,2)="62","0"&MID(D25,3,LEN(D25)),D25) -> 081316016661 | L25: =IFERROR( VLOOKUP( TRIM( IF(ISNUMBER(FIND(",",E25)), LEFT(E25,FIND(",",E25)-1), E25 ) ), master!A:B, 2, FALSE ), "Belum ada mapping" ) -> Riau | M25: =IFERROR(__xludf.DUMMYFUNCTION("IF(REGEXMATCH(I25,""Cari Kerja""),1,0) "),0.0) -> 0 | N25: =IFERROR(__xludf.DUMMYFUNCTION("IF(REGEXMATCH(I25,""Upskill""),1,0) "),1.0) -> 1 | O25: =IFERROR(__xludf.DUMMYFUNCTION("IF(REGEXMATCH(I25,""Networking""),1,0) "),0.0) -> 0 | P25: =IFERROR(__xludf.DUMMYFUNCTION("IF(REGEXMATCH(I25,""Switch Career""),1,0) "),0.0) -> 0
A26: 46046.348 | B26: Afdhal Wirahadi | C26: afdhal.wirahadi@gmail.com | D26: 081316016661 | E26: Dumai | F26: Tidak | G26: Freelance | H26: Excel, SQL, Python, Power BI, Tableau | I26: Upskill | J26: LinkedIn | K26: =IF(LEFT(D26,2)="62","0"&MID(D26,3,LEN(D26)),D26) -> 081316016661 | L26: =IFERROR( VLOOKUP( TRIM( IF(ISNUMBER(FIND(",",E26)), LEFT(E26,FIND(",",E26)-1), E26 ) ), master!A:B, 2, FALSE ), "Belum ada mapping" ) -> Riau | M26: =IFERROR(__xludf.DUMMYFUNCTION("IF(REGEXMATCH(I26,""Cari Kerja""),1,0) "),0.0) -> 0 | N26: =IFERROR(__xludf.DUMMYFUNCTION("IF(REGEXMATCH(I26,""Upskill""),1,0) "),1.0) -> 1 | O26: =IFERROR(__xludf.DUMMYFUNCTION("IF(REGEXMATCH(I26,""Networking""),1,0) "),0.0) -> 0 | P26: =IFERROR(__xludf.DUMMYFUNCTION("IF(REGEXMATCH(I26,""Switch Career""),1,0) "),0.0) -> 0
A27: 46122.541 | B27: Afdhal Wirahadi | C27: afdhal.wirahadi@gmail.com | D27: 081316016661 | E27: Pekanbaru | F27: Tidak | G27: Un employee | H27: Excel, Python, Power BI | I27: Upskill, Switch Career | J27: LinkedIn | K27: =IF(LEFT(D27,2)="62","0"&MID(D27,3,LEN(D27)),D27) -> 081316016661 | L27: =IFERROR( VLOOKUP( TRIM( IF(ISNUMBER(FIND(",",E27)), LEFT(E27,FIND(",",E27)-1), E27 ) ), master!A:B, 2, FALSE ), "Belum ada mapping" ) -> Riau | M27: =IFERROR(__xludf.DUMMYFUNCTION("IF(REGEXMATCH(I27,""Cari Kerja""),1,0) "),0.0) -> 0 | N27: =IFERROR(__xludf.DUMMYFUNCTION("IF(REGEXMATCH(I27,""Upskill""),1,0) "),1.0) -> 1 | O27: =IFERROR(__xludf.DUMMYFUNCTION("IF(REGEXMATCH(I27,""Networking""),1,0) "),0.0) -> 0 | P27: =IFERROR(__xludf.DUMMYFUNCTION("IF(REGEXMATCH(I27,""Switch Career""),1,0) "),1.0) -> 1
A28: 46040.421 | B28: Afifa Zahia Prananto | C28: afifa020204@gmail.com | D28: 0881025319045 | E28: Depok | F28: Ya | G28: Politeknik Negeri Jakarta | H28: Excel, SQL, Python, Power BI, Looker Studio | I28: Cari Kerja, Upskill, Networking, Switch Career | J28: LinkedIn | K28: =IF(LEFT(D28,2)="62","0"&MID(D28,3,LEN(D28)),D28) -> 0881025319045 | L28: =IFERROR( VLOOKUP( TRIM( IF(ISNUMBER(FIND(",",E28)), LEFT(E28,FIND(",",E28)-1), E28 ) ), master!A:B, 2, FALSE ), "Belum ada mapping" ) -> Jawa Barat | M28: =IFERROR(__xludf.DUMMYFUNCTION("IF(REGEXMATCH(I28,""Cari Kerja""),1,0) "),1.0) -> 1 | N28: =IFERROR(__xludf.DUMMYFUNCTION("IF(REGEXMATCH(I28,""Upskill""),1,0) "),1.0) -> 1 | O28: =IFERROR(__xludf.DUMMYFUNCTION("IF(REGEXMATCH(I28,""Networking""),1,0) "),1.0) -> 1 | P28: =IFERROR(__xludf.DUMMYFUNCTION("IF(REGEXMATCH(I28,""Switch Career""),1,0) "),1.0) -> 1
A29: 46043.961 | B29: Agam Gunawan Setiaji | C29: agasawork@gmail.com | D29: 085641737295 | E29: Purworejo | F29: Ya | G29: - | H29: Excel, SQL, Python, Looker Studio | I29: Cari Kerja, Upskill, Networking | J29: LinkedIn | K29: =IF(LEFT(D29,2)="62","0"&MID(D29,3,LEN(D29)),D29) -> 085641737295 | L29: =IFERROR( VLOOKUP( TRIM( IF(ISNUMBER(FIND(",",E29)), LEFT(E29,FIND(",",E29)-1), E29 ) ), master!A:B, 2, FALSE ), "Belum ada mapping" ) -> Jawa Tengah | M29: =IFERROR(__xludf.DUMMYFUNCTION("IF(REGEXMATCH(I29,""Cari Kerja""),1,0) "),1.0) -> 1 | N29: =IFERROR(__xludf.DUMMYFUNCTION("IF(REGEXMATCH(I29,""Upskill""),1,0) "),1.0) -> 1 | O29: =IFERROR(__xludf.DUMMYFUNCTION("IF(REGEXMATCH(I29,""Networking""),1,0) "),1.0) -> 1 | P29: =IFERROR(__xludf.DUMMYFUNCTION("IF(REGEXMATCH(I29,""Switch Career""),1,0) "),0.0) -> 0
A30: 46045.845 | B30: Agatha Anggriani Tumanggor | C30: agathatumanggor07@gmail.com | D30: 082184471311 | E30: Medan | F30: Ya | G30: Tidak ada | H30: SQL, Python, Power BI, Looker Studio, Tableau | I30: Cari Kerja | J30: LinkedIn | K30: =IF(LEFT(D30,2)="62","0"&MID(D30,3,LEN(D30)),D30) -> 082184471311 | L30: =IFERROR( VLOOKUP( TRIM( IF(ISNUMBER(FIND(",",E30)), LEFT(E30,FIND(",",E30)-1), E30 ) ), master!A:B, 2, FALSE ), "Belum ada mapping" ) -> Sumatera Utara | M30: =IFERROR(__xludf.DUMMYFUNCTION("IF(REGEXMATCH(I30,""Cari Kerja""),1,0) "),1.0) -> 1 | N30: =IFERROR(__xludf.DUMMYFUNCTION("IF(REGEXMATCH(I30,""Upskill""),1,0) "),0.0) -> 0 | O30: =IFERROR(__xludf.DUMMYFUNCTION("IF(REGEXMATCH(I30,""Networking""),1,0) "),0.0) -> 0 | P30: =IFERROR(__xludf.DUMMYFUNCTION("IF(REGEXMATCH(I30,""Switch Career""),1,0) "),0.0) -> 0
A31: 46047.029 | B31: Ageng Pradikta Maulana | C31: ageng.pradikta@gmail.com | D31: 081228618111 | E31: Malang | F31: Tidak | G31: Sales Area (Infinix Indonesia) | H31: Excel | I31: Cari Kerja, Upskill, Networking, Switch Career | J31: LinkedIn | K31: =IF(LEFT(D31,2)="62","0"&MID(D31,3,LEN(D31)),D31) -> 081228618111 | L31: =IFERROR( VLOOKUP( TRIM( IF(ISNUMBER(FIND(",",E31)), LEFT(E31,FIND(",",E31)-1), E31 ) ), master!A:B, 2, FALSE ), "Belum ada mapping" ) -> Jawa Timur | M31: =IFERROR(__xludf.DUMMYFUNCTION("IF(REGEXMATCH(I31,""Cari Kerja""),1,0) "),1.0) -> 1 | N31: =IFERROR(__xludf.DUMMYFUNCTION("IF(REGEXMATCH(I31,""Upskill""),1,0) "),1.0) -> 1 | O31: =IFERROR(__xludf.DUMMYFUNCTION("IF(REGEXMATCH(I31,""Networking""),1,0) "),1.0) -> 1 | P31: =IFERROR(__xludf.DUMMYFUNCTION("IF(REGEXMATCH(I31,""Switch Career""),1,0) "),1.0) -> 1
A32: 46042.244 | B32: agriffa nuzra djolanda | C32: agriffaanzr@gmail.com | D32: 0895415890030 | E32: Bekasi | F32: Ya | G32: Politeknik Takumi | H32: Excel, Power BI, Looker Studio, Tableau | I32: Cari Kerja, Upskill, Networking, Switch Career | J32: LinkedIn | K32: =IF(LEFT(D32,2)="62","0"&MID(D32,3,LEN(D32)),D32) -> 0895415890030 | L32: =IFERROR( VLOOKUP( TRIM( IF(ISNUMBER(FIND(",",E32)), LEFT(E32,FIND(",",E32)-1), E32 ) ), master!A:B, 2, FALSE ), "Belum ada mapping" ) -> Jawa Barat | M32: =IFERROR(__xludf.DUMMYFUNCTION("IF(REGEXMATCH(I32,""Cari Kerja""),1,0) "),1.0) -> 1 | N32: =IFERROR(__xludf.DUMMYFUNCTION("IF(REGEXMATCH(I32,""Upskill""),1,0) "),1.0) -> 1 | O32: =IFERROR(__xludf.DUMMYFUNCTION("IF(REGEXMATCH(I32,""Networking""),1,0) "),1.0) -> 1 | P32: =IFERROR(__xludf.DUMMYFUNCTION("IF(REGEXMATCH(I32,""Switch Career""),1,0) "),1.0) -> 1
A33: 46046.389 | B33: Agung Nugroho | C33: agg93nugroho@gmail.com | D33: 085117531509 | E33: Jakarta | F33: Tidak | G33: Phl di RS Bhayangkara Tk I Pusdokkes Polri | H33: Excel, SQL, Python, Databases | I33: Cari Kerja, Upskill, Networking, Switch Career | J33: Teman | K33: =IF(LEFT(D33,2)="62","0"&MID(D33,3,LEN(D33)),D33) -> 085117531509 | L33: =IFERROR( VLOOKUP( TRIM( IF(ISNUMBER(FIND(",",E33)), LEFT(E33,FIND(",",E33)-1), E33 ) ), master!A:B, 2, FALSE ), "Belum ada mapping" ) -> Jakarta | M33: =IFERROR(__xludf.DUMMYFUNCTION("IF(REGEXMATCH(I33,""Cari Kerja""),1,0) "),1.0) -> 1 | N33: =IFERROR(__xludf.DUMMYFUNCTION("IF(REGEXMATCH(I33,""Upskill""),1,0) "),1.0) -> 1 | O33: =IFERROR(__xludf.DUMMYFUNCTION("IF(REGEXMATCH(I33,""Networking""),1,0) "),1.0) -> 1 | P33: =IFERROR(__xludf.DUMMYFUNCTION("IF(REGEXMATCH(I33,""Switch Career""),1,0) "),1.0) -> 1
A34: 46042.301 | B34: Agung saputra | C34: agung12saputra2@gmail.com | D34: 081290952870 | E34: Sumatera selatan | F34: Tidak | G34: PT Satria Mayangkara Service | H34: Excel, Looker Studio, Databases | I34: Upskill | J34: LinkedIn | K34: =IF(LEFT(D34,2)="62","0"&MID(D34,3,LEN(D34)),D34) -> 081290952870 | L34: =IFERROR( VLOOKUP( TRIM( IF(ISNUMBER(FIND(",",E34)), LEFT(E34,FIND(",",E34)-1), E34 ) ), master!A:B, 2, FALSE ), "Belum ada mapping" ) -> Sumatera Selatan | M34: =IFERROR(__xludf.DUMMYFUNCTION("IF(REGEXMATCH(I34,""Cari Kerja""),1,0) "),0.0) -> 0 | N34: =IFERROR(__xludf.DUMMYFUNCTION("IF(REGEXMATCH(I34,""Upskill""),1,0) "),1.0) -> 1 | O34: =IFERROR(__xludf.DUMMYFUNCTION("IF(REGEXMATCH(I34,""Networking""),1,0) "),0.0) -> 0 | P34: =IFERROR(__xludf.DUMMYFUNCTION("IF(REGEXMATCH(I34,""Switch Career""),1,0) "),0.0) -> 0
A35: 46048.934 | B35: Agung Turpa | C35: agung.turpa@eatsagala.id | D35: 0895610337754 | E35: Bandung | F35: Tidak | G35: Data operations | H35: Excel, SQL, Python, Databases, Tableau | I35: Upskill, Networking | J35: Teman | K35: =IF(LEFT(D35,2)="62","0"&MID(D35,3,LEN(D35)),D35) -> 0895610337754 | L35: =IFERROR( VLOOKUP( TRIM( IF(ISNUMBER(FIND(",",E35)), LEFT(E35,FIND(",",E35)-1), E35 ) ), master!A:B, 2, FALSE ), "Belum ada mapping" ) -> Jawa Barat | M35: =IFERROR(__xludf.DUMMYFUNCTION("IF(REGEXMATCH(I35,""Cari Kerja""),1,0) "),0.0) -> 0 | N35: =IFERROR(__xludf.DUMMYFUNCTION("IF(REGEXMATCH(I35,""Upskill""),1,0) "),1.0) -> 1 | O35: =IFERROR(__xludf.DUMMYFUNCTION("IF(REGEXMATCH(I35,""Networking""),1,0) "),1.0) -> 1 | P35: =IFERROR(__xludf.DUMMYFUNCTION("IF(REGEXMATCH(I35,""Switch Career""),1,0) "),0.0) -> 0
A36: 46042.327 | B36: Ahmad Aan Said Daroini | C36: ahmadaansaiddaroini@gmail.com | D36: 085608185322 | E36: Surabaya | F36: Tidak | G36: Admin support - PT Garis Pertama Solusi | H36: SQL, Python, Power BI, Looker Studio | I36: Cari Kerja, Upskill, Networking | J36: LinkedIn | K36: =IF(LEFT(D36,2)="62","0"&MID(D36,3,LEN(D36)),D36) -> 085608185322 | L36: =IFERROR( VLOOKUP( TRIM( IF(ISNUMBER(FIND(",",E36)), LEFT(E36,FIND(",",E36)-1), E36 ) ), master!A:B, 2, FALSE ), "Belum ada mapping" ) -> Jawa Timur | M36: =IFERROR(__xludf.DUMMYFUNCTION("IF(REGEXMATCH(I36,""Cari Kerja""),1,0) "),1.0) -> 1 | N36: =IFERROR(__xludf.DUMMYFUNCTION("IF(REGEXMATCH(I36,""Upskill""),1,0) "),1.0) -> 1 | O36: =IFERROR(__xludf.DUMMYFUNCTION("IF(REGEXMATCH(I36,""Networking""),1,0) "),1.0) -> 1 | P36: =IFERROR(__xludf.DUMMYFUNCTION("IF(REGEXMATCH(I36,""Switch Career""),1,0) "),0.0) -> 0
A37: 46042.489 | B37: Ahmad Barra | C37: abvicra@gmail.com | D37: 085156639669 | E37: Jakarta | F37: Tidak | G37: Pegawai Swasta - Corporate Banking Relationship Manager | H37: Excel, SQL, Python, Power BI, Databases, Tableau | I37: Cari Kerja, Upskill, Networking, Switch Career | J37: Instagram | K37: =IF(LEFT(D37,2)="62","0"&MID(D37,3,LEN(D37)),D37) -> 085156639669 | L37: =IFERROR( VLOOKUP( TRIM( IF(ISNUMBER(FIND(",",E37)), LEFT(E37,FIND(",",E37)-1), E37 ) ), master!A:B, 2, FALSE ), "Belum ada mapping" ) -> Jakarta | M37: =IFERROR(__xludf.DUMMYFUNCTION("IF(REGEXMATCH(I37,""Cari Kerja""),1,0) "),1.0) -> 1 | N37: =IFERROR(__xludf.DUMMYFUNCTION("IF(REGEXMATCH(I37,""Upskill""),1,0) "),1.0) -> 1 | O37: =IFERROR(__xludf.DUMMYFUNCTION("IF(REGEXMATCH(I37,""Networking""),1,0) "),1.0) -> 1 | P37: =IFERROR(__xludf.DUMMYFUNCTION("IF(REGEXMATCH(I37,""Switch Career""),1,0) "),1.0) -> 1
A38: 46043.292 | B38: AHMAD FADILLAH HARAHAp | C38: afadillah117@gmail.com | D38: 087768885573 | E38: Medan | F38: Ya | G38: Fresh graduate | H38: Excel, Python, Databases | I38: Cari Kerja, Upskill, Networking, Switch Career | J38: Instagram | K38: =IF(LEFT(D38,2)="62","0"&MID(D38,3,LEN(D38)),D38) -> 087768885573 | L38: =IFERROR( VLOOKUP( TRIM( IF(ISNUMBER(FIND(",",E38)), LEFT(E38,FIND(",",E38)-1), E38 ) ), master!A:B, 2, FALSE ), "Belum ada mapping" ) -> Sumatera Utara | M38: =IFERROR(__xludf.DUMMYFUNCTION("IF(REGEXMATCH(I38,""Cari Kerja""),1,0) "),1.0) -> 1 | N38: =IFERROR(__xludf.DUMMYFUNCTION("IF(REGEXMATCH(I38,""Upskill""),1,0) "),1.0) -> 1 | O38: =IFERROR(__xludf.DUMMYFUNCTION("IF(REGEXMATCH(I38,""Networking""),1,0) "),1.0) -> 1 | P38: =IFERROR(__xludf.DUMMYFUNCTION("IF(REGEXMATCH(I38,""Switch Career""),1,0) "),1.0) -> 1
A39: 46043.262 | B39: Ahmad Fauzi | C39: ahmadfauzi040602@gmail.com | D39: 087781094363 | E39: Tangerang Selatan | F39: Ya | G39: UIN Jakarta | H39: Excel, SQL, Python, Power BI, Looker Studio, Databases, Tableau | I39: Cari Kerja, Upskill, Networking | J39: LinkedIn | K39: =IF(LEFT(D39,2)="62","0"&MID(D39,3,LEN(D39)),D39) -> 087781094363 | L39: =IFERROR( VLOOKUP( TRIM( IF(ISNUMBER(FIND(",",E39)), LEFT(E39,FIND(",",E39)-1), E39 ) ), master!A:B, 2, FALSE ), "Belum ada mapping" ) -> Banten | M39: =IFERROR(__xludf.DUMMYFUNCTION("IF(REGEXMATCH(I39,""Cari Kerja""),1,0) "),1.0) -> 1 | N39: =IFERROR(__xludf.DUMMYFUNCTION("IF(REGEXMATCH(I39,""Upskill""),1,0) "),1.0) -> 1 | O39: =IFERROR(__xludf.DUMMYFUNCTION("IF(REGEXMATCH(I39,""Networking""),1,0) "),1.0) -> 1 | P39: =IFERROR(__xludf.DUMMYFUNCTION("IF(REGEXMATCH(I39,""Switch Career""),1,0) "),0.0) -> 0
A40: 46046.535 | B40: ahmad ilham | C40: bastian.ilham@hotmail.com | D40: 08987503222 | E40: tangerang selatan | F40: Tidak | G40: finance | H40: SQL, Python, Power BI, Looker Studio, Databases, Tableau | I40: Upskill | J40: LinkedIn | K40: =IF(LEFT(D40,2)="62","0"&MID(D40,3,LEN(D40)),D40) -> 08987503222 | L40: =IFERROR( VLOOKUP( TRIM( IF(ISNUMBER(FIND(",",E40)), LEFT(E40,FIND(",",E40)-1), E40 ) ), master!A:B, 2, FALSE ), "Belum ada mapping" ) -> Banten | M40: =IFERROR(__xludf.DUMMYFUNCTION("IF(REGEXMATCH(I40,""Cari Kerja""),1,0) "),0.0) -> 0 | N40: =IFERROR(__xludf.DUMMYFUNCTION("IF(REGEXMATCH(I40,""Upskill""),1,0) "),1.0) -> 1 | O40: =IFERROR(__xludf.DUMMYFUNCTION("IF(REGEXMATCH(I40,""Networking""),1,0) "),0.0) -> 0 | P40: =IFERROR(__xludf.DUMMYFUNCTION("IF(REGEXMATCH(I40,""Switch Career""),1,0) "),0.0) -> 0
...

Sheet master
A1: Domisili | B1: Provinsi
A2: Aceh | B2: Aceh
A3: Aceh Utara | B3: Aceh
A4: Denpasar | B4: Bali
A5: Belitung | B5: Bangka Belitung
A6: Banten | B6: Banten
A7: BSD | B7: Banten
A8: Cilegon | B8: Banten
A9: Kab. Tangerang | B9: Banten
A10: Pamulang | B10: Banten
A11: Rangkasbitung | B11: Banten
A12: Serang | B12: Banten
... A146: Sumatra Selatan | B146: Sumatra Selatan

Sheet dataset
A1: id | B1: {='Form Responses 1'!E:J} -> Domisili | C1: Apakah Anda Mahasiswa / Fresh Graduate | D1: Pekerjaan & Instansi Saat Ini | E1: Tools yang Ingin Dipelajari | F1: Target Join Komunitas | G1: Tau Seara Data Dari Mana? | H1: Provinsi | I1: Cari Kerja
A2: 1 | B2: Jawa Tengah | C2: Ya | D2: Mahasiswa | E2: Python, Tableau | F2: Cari Kerja, Upskill, Networking | G2: LinkedIn | H2: =IFERROR(VLOOKUP(TRIM(IF(ISNUMBER(FIND(",", B2)),LEFT(B2,FIND(",",B2)-1),B2)),master!A:B,2,FALSE),"Belum ada mapping") -> Jawa Tengah | I2: =IFERROR(__xludf.DUMMYFUNCTION("IF(REGEXMATCH(F2,""Cari Kerja""),1,0)"),1.0) -> 1
A3: 2 | B3: Padang | C3: Ya | D3: belum ada | E3: Excel, SQL, Python, Power BI | F3: Cari Kerja, Upskill, Networking, Switch Career | G3: LinkedIn | H3: =IFERROR(VLOOKUP(TRIM(IF(ISNUMBER(FIND(",", B3)),LEFT(B3,FIND(",",B3)-1),B3)),master!A:B,2,FALSE),"Belum ada mapping") -> Sumatera Barat | I3: =IFERROR(__xludf.DUMMYFUNCTION("IF(REGEXMATCH(F3,""Cari Kerja""),1,0)"),1.0) -> 1
A4: 3 | B4: Surabaya | C4: Ya | D4: Freelance Web Development | E4: Excel, SQL, Python, Power BI, Databases | F4: Cari Kerja, Upskill, Networking | G4: Teman | H4: =IFERROR(VLOOKUP(TRIM(IF(ISNUMBER(FIND(",", B4)),LEFT(B4,FIND(",",B4)-1),B4)),master!A:B,2,FALSE),"Belum ada mapping") -> Jawa Timur | I4: =IFERROR(__xludf.DUMMYFUNCTION("IF(REGEXMATCH(F4,""Cari Kerja""),1,0)"),1.0) -> 1
A5: 4 | B5: Bandung | C5: Ya | D5: Konsultan Perencanaan Kota | E5: Python, Power BI | F5: Upskill | G5: LinkedIn | H5: =IFERROR(VLOOKUP(TRIM(IF(ISNUMBER(FIND(",", B5)),LEFT(B5,FIND(",",B5)-1),B5)),master!A:B,2,FALSE),"Belum ada mapping") -> Jawa Barat | I5: =IFERROR(__xludf.DUMMYFUNCTION("IF(REGEXMATCH(F5,""Cari Kerja""),1,0)"),0.0) -> 0
A6: 5 | B6: Yogyakarta | C6: Tidak | D6: Senior Barista _- Esha kopi | E6: Excel, SQL, Python, Power BI, Looker Studio, Databases, Tableau | F6: Upskill, Networking, Switch Career | G6: Teman | H6: =IFERROR(VLOOKUP(TRIM(IF(ISNUMBER(FIND(",", B6)),LEFT(B6,FIND(",",B6)-1),B6)),master!A:B,2,FALSE),"Belum ada mapping") -> DI Yogyakarta | I6: =IFERROR(__xludf.DUMMYFUNCTION("IF(REGEXMATCH(F6,""Cari Kerja""),1,0)"),0.0) -> 0
A7: 6 | B7: Tangerang | C7: Ya | D7: Data & Informasi System Staff, Kementerian Desa PDT | E7: Excel, SQL, Power BI, Tableau | F7: Upskill, Networking | G7: Teman | H7: =IFERROR(VLOOKUP(TRIM(IF(ISNUMBER(FIND(",", B7)),LEFT(B7,FIND(",",B7)-1),B7)),master!A:B,2,FALSE),"Belum ada mapping") -> Banten | I7: =IFERROR(__xludf.DUMMYFUNCTION("IF(REGEXMATCH(F7,""Cari Kerja""),1,0)"),0.0) -> 0
A8: 7 | B8: Kudus | C8: Tidak | D8: Admin Personalia | E8: Excel, SQL, Python, Power BI, Looker Studio, Databases, Tableau | F8: Cari Kerja, Upskill, Networking, Switch Career | G8: LinkedIn | H8: =IFERROR(VLOOKUP(TRIM(IF(ISNUMBER(FIND(",", B8)),LEFT(B8,FIND(",",B8)-1),B8)),master!A:B,2,FALSE),"Belum ada mapping") -> Jawa Tengah | I8: =IFERROR(__xludf.DUMMYFUNCTION("IF(REGEXMATCH(F8,""Cari Kerja""),1,0)"),1.0) -> 1
A9: 8 | B9: Boyolali | C9: Ya | D9: - | E9: Excel, SQL, Python, Power BI, Looker Studio, Databases, Airflow | F9: Cari Kerja, Upskill, Networking | G9: LinkedIn | H9: =IFERROR(VLOOKUP(TRIM(IF(ISNUMBER(FIND(",", B9)),LEFT(B9,FIND(",",B9)-1),B9)),master!A:B,2,FALSE),"Belum ada mapping") -> Jawa Tengah | I9: =IFERROR(__xludf.DUMMYFUNCTION("IF(REGEXMATCH(F9,""Cari Kerja""),1,0)"),1.0) -> 1
A10: 9 | B10: Tangerang | C10: Tidak | D10: Senior Business Intelegence Dekoruma | E10: Excel, SQL, Python, Power BI, Looker Studio, Databases, Tableau | F10: Upskill, Networking | G10: Instagram | H10: =IFERROR(VLOOKUP(TRIM(IF(ISNUMBER(FIND(",", B10)),LEFT(B10,FIND(",",B10)-1),B10)),master!A:B,2,FALSE),"Belum ada mapping") -> Banten | I10: =IFERROR(__xludf.DUMMYFUNCTION("IF(REGEXMATCH(F10,""Cari Kerja""),1,0)"),0.0) -> 0
A11: 10 | B11: Sidoarjo, Jawa Timur | C11: Tidak | D11: Audit - PT Jawa Berkat Indonesia | E11: Excel, SQL, Python, Power BI, Looker Studio, Tableau | F11: Cari Kerja, Upskill, Networking, Switch Career | G11: Teman | H11: =IFERROR(VLOOKUP(TRIM(IF(ISNUMBER(FIND(",", B11)),LEFT(B11,FIND(",",B11)-1),B11)),master!A:B,2,FALSE),"Belum ada mapping") -> Jawa Timur | I11: =IFERROR(__xludf.DUMMYFUNCTION("IF(REGEXMATCH(F11,""Cari Kerja""),1,0)"),1.0) -> 1
A12: 11 | B12: Banyumas | C12: Ya | D12: - | E12: Excel, SQL, Python, Power BI, Looker Studio, Databases | F12: Cari Kerja | G12: Instagram | H12: =IFERROR(VLOOKUP(TRIM(IF(ISNUMBER(FIND(",", B12)),LEFT(B12,FIND(",",B12)-1),B12)),master!A:B,2,FALSE),"Belum ada mapping") -> Jawa Tengah | I12: =IFERROR(__xludf.DUMMYFUNCTION("IF(REGEXMATCH(F12,""Cari Kerja""),1,0)"),1.0) -> 1
A13: 12 | B13: Jawa Tengah | C13: Ya | D13: - | E13: Excel, SQL, Python, Power BI, Looker Studio, Databases, Tableau | F13: Cari Kerja, Upskill, Networking | G13: LinkedIn | H13: =IFERROR(VLOOKUP(TRIM(IF(ISNUMBER(FIND(",", B13)),LEFT(B13,FIND(",",B13)-1),B13)),master!A:B,2,FALSE),"Belum ada mapping") -> Jawa Tengah | I13: =IFERROR(__xludf.DUMMYFUNCTION("IF(REGEXMATCH(F13,""Cari Kerja""),1,0)"),1.0) -> 1
A14: 13 | B14: Bekasi | C14: Ya | D14: - | E14: Excel, SQL, Python, Power BI, Tableau | F14: Upskill | G14: Teman | H14: =IFERROR(VLOOKUP(TRIM(IF(ISNUMBER(FIND(",", B14)),LEFT(B14,FIND(",",B14)-1),B14)),master!A:B,2,FALSE),"Belum ada mapping") -> Jawa Barat | I14: =IFERROR(__xludf.DUMMYFUNCTION("IF(REGEXMATCH(F14,""Cari Kerja""),1,0)"),0.0) -> 0
A15: 14 | B15: Jakarta Timur | C15: Tidak | D15: Warehouse - Supply Chain | E15: Excel, SQL, Python, Power BI | F15: Upskill, Networking | G15: LinkedIn | H15: =IFERROR(VLOOKUP(TRIM(IF(ISNUMBER(FIND(",", B15)),LEFT(B15,FIND(",",B15)-1),B15)),master!A:B,2,FALSE),"Belum ada mapping") -> Jakarta | I15: =IFERROR(__xludf.DUMMYFUNCTION("IF(REGEXMATCH(F15,""Cari Kerja""),1,0)"),0.0) -> 0
A16: 15 | B16: Padang | C16: Tidak | D16: ASN | E16: Excel, SQL, Python, Power BI, Looker Studio, Databases, Tableau, Anything | F16: Cari Kerja, Upskill, Networking, Switch Career | G16: LinkedIn | H16: =IFERROR(VLOOKUP(TRIM(IF(ISNUMBER(FIND(",", B16)),LEFT(B16,FIND(",",B16)-1),B16)),master!A:B,2,FALSE),"Belum ada mapping") -> Sumatera Barat | I16: =IFERROR(__xludf.DUMMYFUNCTION("IF(REGEXMATCH(F16,""Cari Kerja""),1,0)"),1.0) -> 1
A17: 16 | B17: Cianjur | C17: Tidak | D17: Staff HR di salah satu Bank Swasta | E17: Excel, SQL, Python, Power BI, Databases | F17: Cari Kerja, Networking | G17: Teman | H17: =IFERROR(VLOOKUP(TRIM(IF(ISNUMBER(FIND(",", B17)),LEFT(B17,FIND(",",B17)-1),B17)),master!A:B,2,FALSE),"Belum ada mapping") -> Jawa Barat | I17: =IFERROR(__xludf.DUMMYFUNCTION("IF(REGEXMATCH(F17,""Cari Kerja""),1,0)"),1.0) -> 1
A18: 17 | B18: Medan | C18: Tidak | D18: Idle | E18: Excel, SQL, Python, Power BI, Looker Studio, Databases, Tableau | F18: Cari Kerja, Upskill, Networking, Switch Career | G18: LinkedIn | H18: =IFERROR(VLOOKUP(TRIM(IF(ISNUMBER(FIND(",", B18)),LEFT(B18,FIND(",",B18)-1),B18)),master!A:B,2,FALSE),"Belum ada mapping") -> Sumatera Utara | I18: =IFERROR(__xludf.DUMMYFUNCTION("IF(REGEXMATCH(F18,""Cari Kerja""),1,0)"),1.0) -> 1
A19: 18 | B19: Gresik | C19: Ya | D19: Mahasiswa | E19: Excel, SQL, Python, Power BI, Tableau | F19: Cari Kerja, Upskill, Networking | G19: LinkedIn | H19: =IFERROR(VLOOKUP(TRIM(IF(ISNUMBER(FIND(",", B19)),LEFT(B19,FIND(",",B19)-1),B19)),master!A:B,2,FALSE),"Belum ada mapping") -> Jawa Timur | I19: =IFERROR(__xludf.DUMMYFUNCTION("IF(REGEXMATCH(F19,""Cari Kerja""),1,0)"),1.0) -> 1
A20: 19 | B20: Makassar | C20: Ya | D20: Quality System Intern | E20: Excel, SQL, Python, Power BI, Looker Studio, Databases, Tableau | F20: Cari Kerja, Upskill, Networking | G20: LinkedIn | H20: =IFERROR(VLOOKUP(TRIM(IF(ISNUMBER(FIND(",", B20)),LEFT(B20,FIND(",",B20)-1),B20)),master!A:B,2,FALSE),"Belum ada mapping") -> Sulawesi Selatan | I20: =IFERROR(__xludf.DUMMYFUNCTION("IF(REGEXMATCH(F20,""Cari Kerja""),1,0)"),1.0) -> 1
A21: 20 | B21: Jawa Barat, | C21: Ya | D21: Freshgraduated | E21: Excel, SQL, Power BI, Looker Studio | F21: Cari Kerja, Upskill | G21: LinkedIn | H21: =IFERROR(VLOOKUP(TRIM(IF(ISNUMBER(FIND(",", B21)),LEFT(B21,FIND(",",B21)-1),B21)),master!A:B,2,FALSE),"Belum ada mapping") -> Jawa Barat | I21: =IFERROR(__xludf.DUMMYFUNCTION("IF(REGEXMATCH(F21,""Cari Kerja""),1,0)"),1.0) -> 1
A22: 21 | B22: Bandung | C22: Ya | D22: Magang - Pemerintahan (BBPMP Jabar) | E22: Power BI, Looker Studio, Tableau | F22: Cari Kerja, Upskill | G22: LinkedIn | H22: =IFERROR(VLOOKUP(TRIM(IF(ISNUMBER(FIND(",", B22)),LEFT(B22,FIND(",",B22)-1),B22)),master!A:B,2,FALSE),"Belum ada mapping") -> Jawa Barat | I22: =IFERROR(__xludf.DUMMYFUNCTION("IF(REGEXMATCH(F22,""Cari Kerja""),1,0)"),1.0) -> 1
A23: 22 | B23: Bekasi | C23: Tidak | D23: PT SOKKA TAMA FIBER | E23: Excel, SQL, Python, Power BI, Looker Studio, Databases, Tableau | F23: Upskill, Networking, Switch Career | G23: Instagram | H23: =IFERROR(VLOOKUP(TRIM(IF(ISNUMBER(FIND(",", B23)),LEFT(B23,FIND(",",B23)-1),B23)),master!A:B,2,FALSE),"Belum ada mapping") -> Jawa Barat | I23: =IFERROR(__xludf.DUMMYFUNCTION("IF(REGEXMATCH(F23,""Cari Kerja""),1,0)"),0.0) -> 0
A24: 23 | B24: Tangerang | C24: Ya | D24: Student | E24: Excel, SQL, Python, Power BI, Looker Studio, Databases, Tableau | F24: Upskill, Networking | G24: LinkedIn | H24: =IFERROR(VLOOKUP(TRIM(IF(ISNUMBER(FIND(",", B24)),LEFT(B24,FIND(",",B24)-1),B24)),master!A:B,2,FALSE),"Belum ada mapping") -> Banten | I24: =IFERROR(__xludf.DUMMYFUNCTION("IF(REGEXMATCH(F24,""Cari Kerja""),1,0)"),0.0) -> 0
A25: 24 | B25: Dumai | C25: Tidak | D25: Freelance | E25: Excel, SQL, Python, Power BI, Tableau | F25: Upskill | G25: LinkedIn | H25: =IFERROR(VLOOKUP(TRIM(IF(ISNUMBER(FIND(",", B25)),LEFT(B25,FIND(",",B25)-1),B25)),master!A:B,2,FALSE),"Belum ada mapping") -> Riau | I25: =IFERROR(__xludf.DUMMYFUNCTION("IF(REGEXMATCH(F25,""Cari Kerja""),1,0)"),0.0) -> 0
A26: 25 | B26: Dumai | C26: Tidak | D26: Freelance | E26: Excel, SQL, Python, Power BI, Tableau | F26: Upskill | G26: LinkedIn | H26: =IFERROR(VLOOKUP(TRIM(IF(ISNUMBER(FIND(",", B26)),LEFT(B26,FIND(",",B26)-1),B26)),master!A:B,2,FALSE),"Belum ada mapping") -> Riau | I26: =IFERROR(__xludf.DUMMYFUNCTION("IF(REGEXMATCH(F26,""Cari Kerja""),1,0)"),0.0) -> 0
A27: 26 | B27: Pekanbaru | C27: Tidak | D27: Un employee | E27: Excel, Python, Power BI | F27: Upskill, Switch Career | G27: LinkedIn | H27: =IFERROR(VLOOKUP(TRIM(IF(ISNUMBER(FIND(",", B27)),LEFT(B27,FIND(",",B27)-1),B27)),master!A:B,2,FALSE),"Belum ada mapping") -> Riau | I27: =IFERROR(__xludf.DUMMYFUNCTION("IF(REGEXMATCH(F27,""Cari Kerja""),1,0)"),0.0) -> 0
A28: 27 | B28: Depok | C28: Ya | D28: Politeknik Negeri Jakarta | E28: Excel, SQL, Python, Power BI, Looker Studio | F28: Cari Kerja, Upskill, Networking, Switch Career | G28: LinkedIn | H28: =IFERROR(VLOOKUP(TRIM(IF(ISNUMBER(FIND(",", B28)),LEFT(B28,FIND(",",B28)-1),B28)),master!A:B,2,FALSE),"Belum ada mapping") -> Jawa Barat | I28: =IFERROR(__xludf.DUMMYFUNCTION("IF(REGEXMATCH(F28,""Cari Kerja""),1,0)"),1.0) -> 1
A29: 28 | B29: Purworejo | C29: Ya | D29: - | E29: Excel, SQL, Python, Looker Studio | F29: Cari Kerja, Upskill, Networking | G29: LinkedIn | H29: =IFERROR(VLOOKUP(TRIM(IF(ISNUMBER(FIND(",", B29)),LEFT(B29,FIND(",",B29)-1),B29)),master!A:B,2,FALSE),"Belum ada mapping") -> Jawa Tengah | I29: =IFERROR(__xludf.DUMMYFUNCTION("IF(REGEXMATCH(F29,""Cari Kerja""),1,0)"),1.0) -> 1
A30: 29 | B30: Medan | C30: Ya | D30: Tidak ada | E30: SQL, Python, Power BI, Looker Studio, Tableau | F30: Cari Kerja | G30: LinkedIn | H30: =IFERROR(VLOOKUP(TRIM(IF(ISNUMBER(FIND(",", B30)),LEFT(B30,FIND(",",B30)-1),B30)),master!A:B,2,FALSE),"Belum ada mapping") -> Sumatera Utara | I30: =IFERROR(__xludf.DUMMYFUNCTION("IF(REGEXMATCH(F30,""Cari Kerja""),1,0)"),1.0) -> 1
A31: 30 | B31: Malang | C31: Tidak | D31: Sales Area (Infinix Indonesia) | E31: Excel | F31: Cari Kerja, Upskill, Networking, Switch Career | G31: LinkedIn | H31: =IFERROR(VLOOKUP(TRIM(IF(ISNUMBER(FIND(",", B31)),LEFT(B31,FIND(",",B31)-1),B31)),master!A:B,2,FALSE),"Belum ada mapping") -> Jawa Timur | I31: =IFERROR(__xludf.DUMMYFUNCTION("IF(REGEXMATCH(F31,""Cari Kerja""),1,0)"),1.0) -> 1
A32: 31 | B32: Bekasi | C32: Ya | D32: Politeknik Takumi | E32: Excel, Power BI, Looker Studio, Tableau | F32: Cari Kerja, Upskill, Networking, Switch Career | G32: LinkedIn | H32: =IFERROR(VLOOKUP(TRIM(IF(ISNUMBER(FIND(",", B32)),LEFT(B32,FIND(",",B32)-1),B32)),master!A:B,2,FALSE),"Belum ada mapping") -> Jawa Barat | I32: =IFERROR(__xludf.DUMMYFUNCTION("IF(REGEXMATCH(F32,""Cari Kerja""),1,0)"),1.0) -> 1
A33: 32 | B33: Jakarta | C33: Tidak | D33: Phl di RS Bhayangkara Tk I Pusdokkes Polri | E33: Excel, SQL, Python, Databases | F33: Cari Kerja, Upskill, Networking, Switch Career | G33: Teman | H33: =IFERROR(VLOOKUP(TRIM(IF(ISNUMBER(FIND(",", B33)),LEFT(B33,FIND(",",B33)-1),B33)),master!A:B,2,FALSE),"Belum ada mapping") -> Jakarta | I33: =IFERROR(__xludf.DUMMYFUNCTION("IF(REGEXMATCH(F33,""Cari Kerja""),1,0)"),1.0) -> 1
A34: 33 | B34: Sumatera selatan | C34: Tidak | D34: PT Satria Mayangkara Service | E34: Excel, Looker Studio, Databases | F34: Upskill | G34: LinkedIn | H34: =IFERROR(VLOOKUP(TRIM(IF(ISNUMBER(FIND(",", B34)),LEFT(B34,FIND(",",B34)-1),B34)),master!A:B,2,FALSE),"Belum ada mapping") -> Sumatera Selatan | I34: =IFERROR(__xludf.DUMMYFUNCTION("IF(REGEXMATCH(F34,""Cari Kerja""),1,0)"),0.0) -> 0
A35: 34 | B35: Bandung | C35: Tidak | D35: Data operations | E35: Excel, SQL, Python, Databases, Tableau | F35: Upskill, Networking | G35: Teman | H35: =IFERROR(VLOOKUP(TRIM(IF(ISNUMBER(FIND(",", B35)),LEFT(B35,FIND(",",B35)-1),B35)),master!A:B,2,FALSE),"Belum ada mapping") -> Jawa Barat | I35: =IFERROR(__xludf.DUMMYFUNCTION("IF(REGEXMATCH(F35,""Cari Kerja""),1,0)"),0.0) -> 0
A36: 35 | B36: Surabaya | C36: Tidak | D36: Admin support - PT Garis Pertama Solusi | E36: SQL, Python, Power BI, Looker Studio | F36: Cari Kerja, Upskill, Networking | G36: LinkedIn | H36: =IFERROR(VLOOKUP(TRIM(IF(ISNUMBER(FIND(",", B36)),LEFT(B36,FIND(",",B36)-1),B36)),master!A:B,2,FALSE),"Belum ada mapping") -> Jawa Timur | I36: =IFERROR(__xludf.DUMMYFUNCTION("IF(REGEXMATCH(F36,""Cari Kerja""),1,0)"),1.0) -> 1
A37: 36 | B37: Jakarta | C37: Tidak | D37: Pegawai Swasta - Corporate Banking Relationship Manager | E37: Excel, SQL, Python, Power BI, Databases, Tableau | F37: Cari Kerja, Upskill, Networking, Switch Career | G37: Instagram | H37: =IFERROR(VLOOKUP(TRIM(IF(ISNUMBER(FIND(",", B37)),LEFT(B37,FIND(",",B37)-1),B37)),master!A:B,2,FALSE),"Belum ada mapping") -> Jakarta | I37: =IFERROR(__xludf.DUMMYFUNCTION("IF(REGEXMATCH(F37,""Cari Kerja""),1,0)"),1.0) -> 1
A38: 37 | B38: Medan | C38: Ya | D38: Fresh graduate | E38: Excel, Python, Databases | F38: Cari Kerja, Upskill, Networking, Switch Career | G38: Instagram | H38: =IFERROR(VLOOKUP(TRIM(IF(ISNUMBER(FIND(",", B38)),LEFT(B38,FIND(",",B38)-1),B38)),master!A:B,2,FALSE),"Belum ada mapping") -> Sumatera Utara | I38: =IFERROR(__xludf.DUMMYFUNCTION("IF(REGEXMATCH(F38,""Cari Kerja""),1,0)"),1.0) -> 1
A39: 38 | B39: Tangerang Selatan | C39: Ya | D39: UIN Jakarta | E39: Excel, SQL, Python, Power BI, Looker Studio, Databases, Tableau | F39: Cari Kerja, Upskill, Networking | G39: LinkedIn | H39: =IFERROR(VLOOKUP(TRIM(IF(ISNUMBER(FIND(",", B39)),LEFT(B39,FIND(",",B39)-1),B39)),master!A:B,2,FALSE),"Belum ada mapping") -> Banten | I39: =IFERROR(__xludf.DUMMYFUNCTION("IF(REGEXMATCH(F39,""Cari Kerja""),1,0)"),1.0) -> 1
A40: 39 | B40: tangerang selatan | C40: Tidak | D40: finance | E40: SQL, Python, Power BI, Looker Studio, Databases, Tableau | F40: Upskill | G40: LinkedIn | H40: =IFERROR(VLOOKUP(TRIM(IF(ISNUMBER(FIND(",", B40)),LEFT(B40,FIND(",",B40)-1),B40)),master!A:B,2,FALSE),"Belum ada mapping") -> Banten | I40: =IFERROR(__xludf.DUMMYFUNCTION("IF(REGEXMATCH(F40,""Cari Kerja""),1,0)"),0.0) -> 0
...
